Workbook

Sheet Rent vs. Buy
B1: Low | C1: High
A3: Increase in Price of New Home vs. Current | B3: 750000 | C3: 1500000
A4: Down Payment Range | B4: 0.3 | C4: 0.3
A5: Down Payment | B5: =+B3*B4 -> 225000 | C5: =+C3*C4 -> 450000
A7: Origination Fee | B7: =+B8*B3 -> 3750 | C7: =+C8*C3 -> 15000 | D7: Fee for processing the loan (may be negotiable)
A8: % of Loan | B8: 0.005 | C8: 0.01
A9: Underwriting Fee | B9: 400 | C9: 900 | D9: Lender fee for evaluating your loan
A10: Appraisal Fee | B10: 300 | C10: 700 | D10: Required to assess home value
A11: Credit Report Fee | B11: 25 | C11: 50 | D11: Pulling your credit
A12: Title Search & Insurance | B12: 500 | C12: 1500 | D12: Protects against ownership disputes
A13: Recording Fees | B13: 100 | C13: 300 | D13: County/city fee to record the new deed
A14: Escrow Fees | B14: 500 | C14: 2000
A15: Fixed Transaction Costs | B15: =+SUM(B9:B14)+B7 -> 5575 | C15: =+SUM(C9:C14)+C7 -> 20450
A16: Total Cash Need to Buy a Larger Home | B16: =+B15+B7+B5 -> 234325 | C16: =+C15+C7+C5 -> 485450
A17: Average | C17: =AVERAGE(B16:C16) -> 359887.5
A18: Less: Positive Net Cash Flow Over Next Three Years | C18: =-Charts!Q43*2.5 -> -165845.79
A19: Total for Medum Term Category | C19: =+C17+C18 -> 194041.71

Sheet MoneyBoard - Key Metrics
A1: Net Worth | B1: Increasing | C1: =+Charts!S9 -> 4648384
A2: Annual Salary + Bonus | B2: Increasing | C2: =+'Cash Flow'!AX10 -> 970000
A3: Annual Net Cash Flow | B3: Stable | C3: =+Charts!Q43 -> 66338.316 | D3: 14% of cash income | F3: 3000 | G3: 12000
A4: Monthly Cash Flow (1) | B4: Stable | C4: =+Charts!T43 -> -4358.5094 | D4: 11 months in a cash outflow position | F4: =+F3/C3 -> 0.045222734 | G4: =+G3/C3 -> 0.18089094
A5: Monthly Expenses (1) | B5: Increasing | C5: =++Charts!T42 -> -24939.42 | D5: High volatility with $20-60K a month
A6: Cash Needed for Next 12 Months | C6: =-OPTIMIZER!J16 -> -129384.79 | D6: Cumulative cash trough (Nov 2025)
A7: Cash Management | C7: Optimizer Notification
A8: Cash in Bank Accounts | B8: Increasing | C8: =+Charts!Z12 -> 372050
A9: Months of Expenses Covered by Cash | C9: =+Charts!Q48 -> 15.815411 | D9: Too conservative
A10: Cash Excess/Deficit Positon | B10: CLICK HERE | C10: =+SUM(OPTIMIZER!E24:E26)-SUM(OPTIMIZER!G24:G26) -> 162684.07
A11: Identified Additional Cash Income / Year | B11: CLICK HERE | C11: =+OPTIMIZER!AZ29 -> 7207.434 | D11: =+TEXT(C11/C3,"0%")&" increase to your cash flow" -> 11% increase to your cash flow
A12: Investments | C12: Optimizer Notification
A13: A: Cash in Investment Accounts to be Deployed | C13: =+Charts!AB137 -> 222965.43
A14: B: Excess cash to be reallocate to investments | C14: =+OPTIMIZER!H27 -> 162684.07
A15: Total Cash You Should Invest Today (A+B): | B15: CLICK HERE | C15: =SUM(C13:C14) -> 385649.51 | D15: =TEXT(C15/Charts!AB148,"0%")&" increase to investments" -> 15% increase to investments

Sheet Execute on Securities Trades
E2: GURU Recommendation | H2: Make Your Selection
C3: Execute Trade? | E3: Product | F3: Expense Ratio | G3: Total Amount | H3: Total Amount | I3: How many months to buy into the position | J3: Monthly Amount
D4: ='Model Portfolios'!H11 -> US Large Cap | E4: Vanguard S&P 500 (VOO) | F4: 0.0003 | G4: ='Model Portfolios'!M11 -> 0 | H4: =G4 -> 0 | I4: 6 | J4: =IF(ISERROR(H4/I4),"-",H4/I4) -> 0
D5: ='Model Portfolios'!H12 -> US Total Market | E5: Vanguard Total Stock Market (VTI) | F5: 0.0003 | G5: ='Model Portfolios'!M12 -> 0 | H5: 0 | I5: 0 | J5: =IF(ISERROR(H5/I5),"-",H5/I5) -> -
D6: ='Model Portfolios'!H13 -> US Large Cap Growth | E6: Invesco QQQ Trust | F6: 0.002 | G6: ='Model Portfolios'!M13 -> 80000 | H6: =G6 -> 80000 | I6: 6 | J6: =IF(ISERROR(H6/I6),"-",H6/I6) -> 13333.333
D7: ='Model Portfolios'!H14 -> US Dividend / Value | E7: Schwab U.S. Dividend Equity ETF | F7: 0.0006 | G7: ='Model Portfolios'!M14 -> 0 | H7: =G7 -> 0 | I7: 6 | J7: =IF(ISERROR(H7/I7),"-",H7/I7) -> 0
D8: ='Model Portfolios'!H15 -> US Small Cap | E8: iShares Russell 2000 ETF (IWM) | F8: 0.0019 | G8: ='Model Portfolios'!M15 -> 0 | H8: =G8 -> 0 | I8: 6 | J8: =IF(ISERROR(H8/I8),"-",H8/I8) -> 0
D9: ='Model Portfolios'!H17 -> Developed International | E9: iShares Core MSCI EAFE ETF | F9: 0.0007 | G9: ='Model Portfolios'!M17 -> 0 | H9: =G9 -> 0 | I9: 6 | J9: =IF(ISERROR(H9/I9),"-",H9/I9) -> 0
D10: ='Model Portfolios'!H18 -> Emerging Markets | E10: iShares Core MSCI Emerging Markets ETF | F10: 0.0009 | G10: ='Model Portfolios'!M18 -> 0 | H10: =G10 -> 0 | I10: 6 | J10: =IF(ISERROR(H10/I10),"-",H10/I10) -> 0
D11: ='Model Portfolios'!H20 -> REITS, Commodities | E11: Invesco Optimum Yield Diversification Commodity | F11: 0.0067 | G11: ='Model Portfolios'!M20/2 -> 0 | H11: =G11 -> 0 | I11: 6 | J11: =IF(ISERROR(H11/I11),"-",H11/I11) -> 0
D12: ='Model Portfolios'!H21 -> Bonds | E12: Bloomberg Aggregate Bond Inex | F12: 0.0067 | G12: ='Model Portfolios'!M21/2 -> 41342.037 | H12: =G12 -> 41342.037 | I12: 6 | J12: =IF(ISERROR(H12/I12),"-",H12/I12) -> 6890.3396
D13: ='Model Portfolios'!H22 -> Crypto | G13: =G11 -> 0 | H13: 0 | I13: 0 | J13: =IF(ISERROR(H13/I13),"-",H13/I13) -> -
B14: Total | G14: =SUM(G4:G13) -> 121342.04 | H14: =SUM(H4:H13) -> 121342.04 | J14: =SUM(J4:J13) -> 20223.673
G15: Remaining Cash | H15: =G14-H14 -> 0

Sheet Model Portfolios
H2: LIQUID BROKERAGE ASSETS | AE2: A growth-leaning portfolio designed for a medium-short time horizon, balancing upside potential with downside protection. It incorporates high-quality U.S. equities, global diversification, and a meaningful bond allocation (10%) to buffer volatility. Ideal for investors who want growth but may need liquidity within 3–5 years. | AF2: A globally diversified, equity-heavy portfolio for investors with a 10-year horizon who are comfortable with market fluctuations. This portfolio tilts toward U.S. total market and growth equities, while still maintaining meaningful international exposure to capture broader global opportunities. | AG2: Built for investors with a long time horizon and high risk tolerance, this portfolio maximizes growth potential through aggressive equity allocations. It includes a strong U.S. tilt with a heavy focus on large cap growth and small cap value, while maintaining robust international exposure.
H3: Cash Available to Allocate
H4: Cash in Brokerage | I4: =+I10 -> 186585.93 | AC4: MODEL PORTFOLIOS
H5: Reallocation from Cash Mgmt | I5: =+OPTIMIZER!AR27-OPTIMIZER!AM27 -> 162684.07 | R5: SELECT YOUR MODEL PORTFOLIO | AC5: CURRENT - moderately more US focused | AI5: moderately more US focused | AO5: heavy us focus with 15-20% international. But chat gpt says that blackrock model portfolios suggest 30-40% | AV5: growth oriented
H6: Next 12 Month Paycheck | I6: =+OPTIMIZER!P27*12+OPTIMIZER!S27 -> 0
H7: Total | I7: =+SUM(I4:I6) -> 349270.01 | L7: =+I7/I25 -> 0.23138126
L8: Reabalancing Your Portfolio with Cash | S8: Your Current Balances | U8: GURU Suggestion | W8: Make Your Selection | Y8: GURU | AA8: Customer Selected | AC8: Portfolio Investment Horizon | AE8: 5 Years | AF8: 10 Year | AG8: 20+ Year | AK8: 5-Year Portfolio | AL8: 10-Year Portfolio | AM8: 20+ Year Portfolio | AQ8: 5-year Portfolio | AR8: 10-year portfolio | AS8: 20+ year portfolio | AX8: 5-year Portfolio | AY8: 10-year portfolio | AZ8: 20+ year portfolio
C9: Category | D9: Current Balances | E9: Your Model Portfolio | F9: Difference Between Current and Model Portfolio | H9: Category | I9: Current Balances | J9: Your Model Portfolio | K9: Difference Between Current and Model Portfolio | L9: + Invest Your Cash in Brokerage | M9: + Cash From Reallocation and Next 12 Months Pay | N9: Ending Balance | O9: Ending Composition | P9: Vs. Your Model Portfolio | R9: Category | S9: Liquid Brokerage | T9: Retirement | U9: Liquid Brokerage | V9: Retirement | W9: Liquid Brokerage | X9: Retirement | Y9: Liquid Brokerage | Z9: Retirement | AA9: Liquid Brokerage | AB9: Retirement | AC9: Category | AD9: Description | AE9: Capital preservation and Liquidity | AF9: Global Core Growth with Equity-Heavy Portfolio | AG9: High Risk Tolerance with Greater U.S. Tilt | AI9: Category | AK9: Conservative Growth with Downside Protection in Bonds | AL9: Global Core Growth with Equity-Heavy Portfolio | AM9: High Risk Tolerance with Greater U.S. Tilt | AO9: Category | AQ9: Conservative growth + Real Assets | AV9: Category | AX9: Conservative growth + Real Assets
C10: Cash | D10: =+Charts!AB130 -> 36379.5 | E10: =+X10*(E$23) -> 0 | F10: =+E10-D10 -> -36379.5 | H10: Cash | I10: =+Charts!AC103 -> 186585.93 | J10: =+W10*(J$23) -> 0 | K10: =+J10-I10 -> -186585.93 | L10: =+K10 -> -186585.93 | M10: 0 | N10: =+L10+I10+M10 -> 0 | O10: =+N10/$N$25 -> 0 | P10: =+W10 -> 0 | R10: =+H10 -> Cash | S10: =+I10/$I$25 -> 0.12360777 | T10: =+D10/$D$25 -> 0.0363795 | U10: 0 | V10: 0 | W10: 0 | X10: 0 | Y10: =+U10*$I$25 -> 0 | Z10: =+X10*$D$25 -> 0 | AA10: =+W10*$I$25 -> 0 | AB10: =+X10*$D$25 -> 0 | AC10: US Large Cap | AD10: Large, stable (S&P 500) | AE10: 0.1 | AF10: 0.15 | AG10: 0.2 | AI10: U.S. Large Cap (S&P 500) | AJ10: VOO (Vanguard S&P 500) | AK10: 0.25 | AO10: U.S. Large Cap (S&P 500) | AP10: S&P 500 | AQ10: 0.25 | AT10: VTI or VOO | AV10: U.S. Large Cap (S&P 500) | AW10: S&P 500 | AX10: 0.25 | BA10: VTI or VOO
C11: US Large Cap | D11: =+Charts!AB126 -> 100000 | E11: =+X11*(E$23) -> 250000 | F11: =+E11-D11 -> 150000 | H11: =+C11 -> US Large Cap | I11: =+Charts!AC106 -> 435000 | J11: =+W11*(J$23) -> 358468.16 | K11: =+J11-I11 -> -76531.84 | L11: 0 | M11: 0 | N11: =+L11+I11+M11 -> 435000 | O11: =+N11/$N$25 -> 0.26013882 | P11: =+W11 -> 0.25 | R11: =+H11 -> US Large Cap | S11: =+I11/$I$25 -> 0.28817489 | T11: =+D11/$D$25 -> 0.1 | U11: =+AF10 -> 0.15 | V11: 0.2 | W11: 0.25 | X11: 0.25 | Y11: =+U11*$I$25 -> 226425 | Z11: =+X11*$D$25 -> 250000 | AA11: =+W11*$I$25 -> 377375 | AB11: =+X11*$D$25 -> 250000 | AC11: US Total Market | AD11: Catch-all allocation (~75% large & ~25% small/mid cap) | AE11: 0.05 | AF11: 0.05 | AG11: 0.05 | AI11: U.S. Total Market | AJ11: VTI (Vanguard Total Stock Market) | AK11: 0 | AL11: 0.4 | AM11: 0.35 | AO11: U.S. Total Market | AP11: 70-80% large cap and 20-30% small & mid cap | AQ11: 0 | AR11: 0.45 | AS11: 0.4 | AV11: U.S. Total Market | AW11: 70-80% large cap and 20-30% small & mid cap | AX11: 0 | AY11: 0.35 | AZ11: 0.3
C12: US Total Market | D12: =+Charts!AB125 -> 400000 | E12: =+X12*(E$23) -> 150000 | F12: =+E12-D12 -> -250000 | H12: =+C12 -> US Total Market | I12: =+Charts!AC105 -> 379877.58 | J12: =+W12*(J$23) -> 143387.26 | K12: =+J12-I12 -> -236490.32 | L12: 0 | N12: =+L12+I12+M12 -> 379877.58 | O12: =+N12/$N$25 -> 0.2271745 | P12: =+W12 -> 0.1 | R12: =+H12 -> US Total Market | S12: =+I12/$I$25 -> 0.25165789 | T12: =+D12/$D$25 -> 0.4 | U12: =+AF11 -> 0.05 | V12: 0.05 | W12: 0.1 | X12: 0.15 | Y12: =+U12*$I$25 -> 75475 | Z12: =+X12*$D$25 -> 150000 | AA12: =+W12*$I$25 -> 150950 | AB12: =+X12*$D$25 -> 150000 | AC12: US Large Cap Growth | AD12: Innovation, tech, volatile | AE12: 0.05 | AF12: 0.1 | AG12: 0.15 | AI12: Large Cap Growth | AJ12: QQQ (Invesco QQQ Trust - Nasdaq 100) or VUG (Vanguard Growth ETF - Russell 1000) | AK12: 0.15 | AL12: 0.15 | AM12: 0.2 | AO12: Large Cap Growth | AP12: Nasdaq 100 | AQ12: 0.15 | AR12: 0.2 | AS12: 0.25 | AV12: Large Cap Growth | AW12: Nasdaq 100 | AX12: 0.15 | AY12: 0.15 | AZ12: 0.2
C13: US Large Cap Growth | D13: 0 | E13: =+X13*(E$23) -> 150000 | F13: =+E13-D13 -> 150000 | H13: =+C13 -> US Large Cap Growth | I13: 0 | J13: =+W13*(J$23) -> 143387.26 | K13: =+J13-I13 -> 143387.26 | L13: 100000 | M13: 80000 | N13: =+L13+I13+M13 -> 180000 | O13: =+N13/$N$25 -> 0.10764365 | P13: =+W13 -> 0.1 | R13: =+H13 -> US Large Cap Growth | S13: =+I13/$I$25 -> 0 | T13: =+D13/$D$25 -> 0 | U13: =+AF12 -> 0.1 | V13: 0.15 | W13: 0.1 | X13: 0.15 | Y13: =+U13*$I$25 -> 150950 | Z13: =+X13*$D$25 -> 150000 | AA13: =+W13*$I$25 -> 150950 | AB13: =+X13*$D$25 -> 150000 | AC13: US Dividend / Value | AD13: Defensive stocks, reliable income, lower volatility | AE13: 0.1 | AF13: 0.05 | AG13: 0.05 | AI13: U.S. Dividend/Quality | AJ13: SCHD (Schwab U.S. Dividend Equity ETF) or DGRO (iShares Core Dividend Growth ETF) | AK13: 0.1 | AO13: U.S. Dividend/Quality | AQ13: 0.1 | AT13: SCHD or DGRO | AV13: U.S. Dividend/Quality | AX13: 0.1 | BA13: SCHD or DGRO
C14: US Dividend / Value | D14: 0 | E14: =+X14*(E$23) -> 50000 | F14: =+E14-D14 -> 50000 | H14: =+C14 -> US Dividend / Value | I14: =+Charts!AC108 -> 94368.991 | J14: =+W14*(J$23) -> 71693.632 | K14: =+J14-I14 -> -22675.359 | N14: =+L14+I14+M14 -> 94368.991 | O14: =+N14/$N$25 -> 0.056434571 | P14: =+W14 -> 0.05 | R14: =+H14 -> US Dividend / Value | S14: =+I14/$I$25 -> 0.062516722 | T14: =+D14/$D$25 -> 0 | U14: =+AF13 -> 0.05 | V14: 0.05 | W14: 0.05 | X14: =+V14 -> 0.05 | Y14: =+U14*$I$25 -> 75475 | Z14: =+X14*$D$25 -> 50000 | AA14: =+W14*$I$25 -> 75475 | AB14: =+X14*$D$25 -> 50000 | AC14: US Small Cap | AD14: Higher growth but more volatile | AE14: 0.05 | AF14: 0.1 | AG14: 0.15 | AI14: U.S. Small Cap | AJ14: VB (Vanguard Small Cap ETF) or IWM (iShares Russell 2000 ETF) | AK14: 0 | AL14: 0.1 | AM14: 0.15 | AO14: U.S. Small Cap | AQ14: 0 | AR14: 0.1 | AS14: 0.15 | AT14: SCHD or DGRO | AV14: U.S. Small Cap | AX14: 0 | AY14: 0.1 | AZ14: 0.1 | BA14: SCHD or DGRO
C15: US Small Cap | D15: =+Charts!AB127 -> 274264.47 | E15: =+X15*(E$23) -> 100000 | F15: =+E15-D15 -> -174264.47 | H15: =+C15 -> US Small Cap | I15: =+Charts!AC107 -> 49317.756 | J15: =+W15*(J$23) -> 84066.319 | K15: =+J15-I15 -> 34748.563 | N15: =+L15+I15+M15 -> 49317.756 | O15: =+N15/$N$25 -> 0.029493019 | P15: =+W15 -> 0.058628861 | R15: =+H15 -> US Small Cap | S15: =+I15/$I$25 -> 0.032671584 | T15: =+D15/$D$25 -> 0.27426447 | U15: =+AF14 -> 0.1 | V15: 0.1 | W15: =1-SUM(W10:W14,W19:W22,W24) -> 0.058628861 | X15: 0.1 | Y15: =+U15*$I$25 -> 150950 | Z15: =+X15*$D$25 -> 100000 | AA15: =+W15*$I$25 -> 88500.265 | AB15: =+X15*$D$25 -> 100000 | AC15: Total US | AD15: Backbone of most portfolios | AE15: =+SUM(AE10:AE14) -> 0.35 | AF15: =+SUM(AF10:AF14) -> 0.45 | AG15: =+SUM(AG10:AG14) -> 0.6 | AI15: Total US | AK15: =+SUM(AK10:AK14) -> 0.5 | AL15: =+SUM(AL10:AL14) -> 0.65 | AM15: =+SUM(AM10:AM14) -> 0.7 | AO15: Total US | AQ15: =+SUM(AQ10:AQ14) -> 0.5 | AR15: =+SUM(AR10:AR14) -> 0.75 | AS15: =+SUM(AS10:AS14) -> 0.8 | AV15: Total US | AX15: =+SUM(AX10:AX14) -> 0.5 | AY15: =+SUM(AY10:AY14) -> 0.6 | AZ15: =+SUM(AZ10:AZ14) -> 0.6
C16: Total US | D16: =+SUM(D11:D15) -> 774264.47 | E16: =+SUM(E11:E15) -> 700000 | F16: =+SUM(F11:F15) -> -74264.475 | H16: Total US | I16: =+SUM(I11:I15) -> 958564.33 | J16: =+SUM(J11:J15) -> 801002.64 | K16: =+SUM(K11:K15) -> -157561.69 | L16: =+SUM(L11:L15) -> 100000 | N16: =+SUM(N11:N15) -> 1138564.3 | O16: =+SUM(O11:O15) -> 0.68088457 | P16: =+SUM(P11:P15) -> 0.55862886 | R16: Total US | S16: =+SUM(S11:S15) -> 0.63502109 | T16: =+SUM(T11:T15) -> 0.77426447 | U16: =+SUM(U11:U15) -> 0.45 | V16: =+SUM(V11:V15) -> 0.55 | W16: =+SUM(W11:W15) -> 0.55862886 | X16: =+SUM(X11:X15) -> 0.7 | Y16: =+U16*$I$25 -> 679275 | Z16: =+X16*$D$25 -> 700000 | AA16: =+W16*$I$25 -> 843250.27 | AB16: =+X16*$D$25 -> 700000 | AC16: Developed International | AD16: European and Japanese markets | AE16: 0.15 | AF16: 0.15 | AG16: 0.2 | AI16: Developed Markets | AJ16: VEA (Vanguard FTSE Deveoped Market ETF) or IEFA (iShares Core MSCI EAFE ETF) | AK16: 0.1 | AL16: 0.15 | AM16: 0.15 | AO16: Developed Markets | AQ16: 0.1 | AR16: 0.1 | AS16: 0.1 | AT16: VEA | AV16: Developed Markets | AX16: 0.1 | AY16: 0.2 | AZ16: 0.2 | BA16: VEA
C17: Developed International | D17: =+Charts!AB124*85% -> 108924.31 | E17: =+X17*(E$23) -> 150000 | F17: =+E17-D17 -> 41075.687 | H17: =+C17 -> Developed International | I17: =+Charts!AC104 -> 116538.3 | J17: =+W17*(J$23) -> 110699.62 | K17: =+J17-I17 -> -5838.6777 | M17: 0 | N17: =+L17+I17+M17 -> 116538.3 | O17: =+N17/$N$25 -> 0.069692268 | P17: =+W17 -> 0.077203247 | R17: =+H17 -> Developed International | S17: =+I17/$I$25 -> 0.077203247 | T17: =+D17/$D$25 -> 0.10892431 | U17: =+AF16 -> 0.15 | V17: 0.2 | W17: =S17 -> 0.077203247 | X17: 0.15 | Y17: =+U17*$I$25 -> 226425 | Z17: =+X17*$D$25 -> 150000 | AA17: =+W17*$I$25 -> 116538.3 | AB17: =+X17*$D$25 -> 150000 | AC17: Emerging Markets | AD17: Fast growing economies | AE17: 0 | AF17: 0.05 | AG17: 0.1 | AI17: Emerging Markets | AJ17: VWO (Vanguard FTSE Emerging Markets ETF) or IEMG (iShares Core MSCI Emerging Markets ETF) | AK17: 0.1 | AL17: 0.1 | AM17: 0.1 | AO17: Emerging Markets | AQ17: 0.1 | AR17: 0.05 | AS17: 0.05 | AT17: VWO | AV17: Emerging Markets | AX17: 0.1 | AY17: 0.1 | AZ17: 0.15 | BA17: VWO
C18: Emerging Markets | D18: =+Charts!AB124*15% -> 19221.938 | E18: =+X18*(E$23) -> 50000 | F18: =+E18-D18 -> 30778.062 | H18: =+C18 -> Emerging Markets | I18: 0 | J18: =+W18*(J$23) -> 0 | K18: =+J18-I18 -> 0 | N18: =+L18+I18+M18 -> 0 | O18: =+N18/$N$25 -> 0 | P18: =+W18 -> 0 | R18: =+H18 -> Emerging Markets | S18: =+I18/$I$25 -> 0 | T18: =+D18/$D$25 -> 0.019221938 | U18: =+AF17 -> 0.05 | V18: 0.1 | W18: 0 | X18: 0.05 | Y18: =+U18*$I$25 -> 75475 | Z18: =+X18*$D$25 -> 50000 | AA18: =+W18*$I$25 -> 0 | AB18: =+X18*$D$25 -> 50000 | AC18: Total International | AE18: =+SUM(AE16:AE17) -> 0.15 | AF18: =+SUM(AF16:AF17) -> 0.2 | AG18: =+SUM(AG16:AG17) -> 0.3 | AI18: Total International | AK18: =+SUM(AK16:AK17) -> 0.2 | AL18: =+SUM(AL16:AL17) -> 0.25 | AM18: =+SUM(AM16:AM17) -> 0.25 | AO18: Total International | AQ18: =+SUM(AQ16:AQ17) -> 0.2 | AR18: =+SUM(AR16:AR17) -> 0.15 | AS18: =+SUM(AS16:AS17) -> 0.15 | AV18: Total Internaitonal | AX18: =+SUM(AX16:AX17) -> 0.2 | AY18: =+SUM(AY16:AY17) -> 0.3 | AZ18: =+SUM(AZ16:AZ17) -> 0.35
C19: Total International | D19: =SUM(D17:D18) -> 128146.25 | E19: =+SUM(E17:E18) -> 200000 | F19: =+SUM(F17:F18) -> 71853.75 | H19: Total International | I19: =SUM(I17:I18) -> 116538.3 | J19: =+SUM(J17:J18) -> 110699.62 | K19: =+SUM(K17:K18) -> -5838.6777 | L19: =+SUM(L17:L18) -> 0 | N19: =+SUM(N17:N18) -> 116538.3 | O19: =+SUM(O17:O18) -> 0.069692268 | P19: =+SUM(P17:P18) -> 0.077203247 | R19: Total International | S19: =+SUM(S17:S18) -> 0.077203247 | T19: =+SUM(T17:T18) -> 0.12814625 | U19: =+SUM(U17:U18) -> 0.2 | V19: =+SUM(V17:V18) -> 0.3 | W19: =+SUM(W17:W18) -> 0.077203247 | X19: =+SUM(X17:X18) -> 0.2 | Y19: =+U19*$I$25 -> 301900 | Z19: =+X19*$D$25 -> 200000 | AA19: =+W19*$I$25 -> 116538.3 | AB19: =+X19*$D$25 -> 200000 | AC19: REITS, Commodities | AD19: Inflation hedge, asset diversification | AE19: 0 | AF19: 0.05 | AG19: 0.1 | AI19: REITS, Commodities | AJ19: VNQ ( Vanguard Real Estate ETF) or PDBC (Invesco Optimum Yield Diversified Commodity) | AK19: 0.1 | AL19: 0.05 | AM19: 0.05 | AO19: REITS, Commodities | AQ19: 0.1 | AR19: 0.05 | AS19: 0.05 | AV19: REITS, Commodities | AX19: 0.1 | AY19: 0.05 | AZ19: 0.05
C20: REITS, Commodities | D20: 0 | E20: =+X20*(E$23) -> 100000 | F20: =+E20-D20 -> 100000 | H20: =+C20 -> REITS, Commodities | I20: 0 | J20: =+W20*(J$23) -> 0 | K20: =+J20-I20 -> 0 | N20: =+L20+I20+M20 -> 0 | O20: =+N20/$N$25 -> 0 | P20: =+W20 -> 0 | R20: =+H20 -> REITS, Commodities | S20: =+I20/$I$25 -> 0 | T20: =+D20/$D$25 -> 0 | U20: =+AF19 -> 0.05 | V20: 0.1 | W20: 0 | X20: =+V20 -> 0.1 | Y20: =+U20*$I$25 -> 75475 | Z20: =+X20*$D$25 -> 100000 | AA20: =+W20*$I$25 -> 0 | AB20: =+X20*$D$25 -> 100000 | AC20: Bonds | AD20: Downside cushion, stability | AE20: 0.5 | AF20: 0.3 | AG20: 0 | AI20: Bonds | AJ20: iShares Core U.S. Aggregate Bond ETF | AK20: 0.2 | AL20: 0.05 | AM20: 0 | AO20: Bonds | AQ20: 0.2 | AR20: 0.05 | AS20: 0 | AV20: Bonds | AX20: 0.2 | AY20: 0.05 | AZ20: 0
C21: Bonds | D21: =+Charts!AB129 -> 61209.776 | E21: =+X21*(E$23) -> 0 | F21: =+E21-D21 -> -61209.776 | H21: =+C21 -> Bonds | I21: 0 | J21: =+W21*(J$23) -> 286774.53 | K21: =+J21-I21 -> 286774.53 | L21: =+-L10-L13 -> 86585.933 | M21: =+M23-M13 -> 82684.075 | N21: =+L21+I21+M21 -> 169270.01 | O21: =+N21/$N$25 -> 0.1012269 | P21: =+W21 -> 0.2 | R21: =+H21 -> Bonds | S21: =+I21/$I$25 -> 0 | T21: =+D21/$D$25 -> 0.061209776 | U21: =+AF20 -> 0.3 | V21: 0 | W21: 0.2 | X21: =+V21 -> 0 | Y21: =+U21*$I$25 -> 452850 | Z21: =+X21*$D$25 -> 0 | AA21: =+W21*$I$25 -> 301900 | AB21: =+X21*$D$25 -> 0 | AC21: Crypto | AD21: If add reduce another category | AE21: 0 | AF21: 0.05 | AG21: 0.05 | AI21: Crypto | AJ21: Bitwise 10 Crypto Index | AK21: 0 | AL21: 0.05 | AM21: 0.05 | AO21: Crypto | AP21: If add maybe reduce U.S. lareg cap growth | AQ21: 0 | AR21: 0.05 | AS21: 0.05 | AV21: Crypto (Optional) | AW21: If add maybe reduce U.S. lareg cap growth | AX21: 0 | AY21: 0.05 | AZ21: 0.05
C22: Crypto | D22: 0 | E22: =+X22*(E$23) -> 0 | F22: =+E22-D22 -> 0 | H22: =+C22 -> Crypto | I22: =+Charts!AC111 -> 9500 | J22: =+W22*(J$23) -> 9024.0411 | K22: =+J22-I22 -> -475.95887 | N22: =+L22+I22+M22 -> 9500 | O22: =+N22/$N$25 -> 0.0056811927 | P22: =+W22 -> 0.0062934747 | R22: =+H22 -> Crypto | S22: =+I22/$I$25 -> 0.0062934747 | T22: =+D22/$D$25 -> 0 | U22: 0 | V22: 0.05 | W22: =S22 -> 0.0062934747 | X22: 0 | Y22: =+U22*$I$25 -> 0 | Z22: =+X22*$D$25 -> 0 | AA22: =+W22*$I$25 -> 9500 | AB22: =+X22*$D$25 -> 0 | AC22: Total | AE22: =+AE15+AE18+AE19+AE20+AE21-AE21 -> 1 | AF22: =+AF15+AF18+AF19+AF20+AF21-AF21 -> 1 | AG22: =AG21+AG15+AG18+AG19+AG20-AG21 -> 1 | AI22: Total | AK22: =+AK15+AK18+AK19+AK20+AK21-AK21 -> 1 | AL22: =+AL15+AL18+AL19+AL20+AL21-AL21 -> 1 | AM22: =+AM15+AM18+AM19+AM20+AM21-AM21 -> 1 | AO22: Total | AQ22: =+AQ15+AQ18+AQ19+AQ20+AQ21-AQ21 -> 1 | AR22: =+AR15+AR18+AR19+AR20+AR21-AR21 -> 1 | AS22: =+AS15+AS18+AS19+AS20+AS21-AS21 -> 1 | AV22: Total | AX22: =+AX15+AX18+AX19+AX20+AX21-AX21 -> 1 | AY22: =+AY15+AY18+AY19+AY20+AY21-AY21 -> 1 | AZ22: =+AZ15+AZ18+AZ19+AZ20+AZ21-AZ21 -> 1
C23: Total | D23: =+D16+D19+D20+D21+D22+D10 -> 1000000 | E23: =+E25-E24 -> 1000000 | H23: Total | I23: =+I16+I19+I20+I21+I22+I10 -> 1271188.6 | J23: =+J25-J24 -> 1433872.6 | L23: =+L16+L19+L20+L21+L22+L10 -> 0 | M23: =I5+I6 -> 162684.07 | N23: =+N16+N19+N20+N21+N22+N10 -> 1433872.6 | O23: =+O16+O19+O20+O21+O22+O10 -> 0.85748493 | P23: =+P16+P19+P20+P21+P22+P10 -> 0.84212558 | R23: Subtotal | S23: =+S16+S19+S20+S21+S22+S10 -> 0.84212558 | T23: =+T16+T19+T20+T21+T22+T10 -> 1 | U23: =+U16+U19+U20+U21+U22+U10 -> 1 | V23: =+V16+V19+V20+V21+V22+V10 -> 1 | W23: =+W16+W19+W20+W21+W22+W10 -> 0.84212558 | X23: =+X16+X19+X20+X21+X22+X10 -> 1 | Y23: =+U23*$I$25 -> 1509500 | Z23: =+X23*$D$25 -> 1000000 | AA23: =+W23*$I$25 -> 1271188.6 | AB23: =+X23*$D$25 -> 1000000
C24: Other single stock holdings | D24: =+Charts!AB128 -> 0 | E24: =+D24 -> 0 | F24: =+E24-D24 -> 0 | H24: =+C24 -> Other single stock holdings | I24: =+Charts!AC110+Charts!AC109 -> 238311.43 | J24: =+I24 -> 238311.43 | K24: =+J24-I24 -> 0 | N24: =+L24+I24+M24 -> 238311.43 | O24: =+N24/$N$25 -> 0.14251507 | P24: =+W24 -> 0.15787442 | R24: =+H24 -> Other single stock holdings | S24: =+I24/$I$25 -> 0.15787442 | T24: =+D24/$D$25 -> 0 | U24: 0 | V24: 0 | W24: =S24 -> 0.15787442 | X24: 0 | Y24: =+U24*$I$25 -> 0 | Z24: =+X24*$D$25 -> 0 | AA24: =+W24*$I$25 -> 238311.43 | AB24: =+X24*$D$25 -> 0
C25: Total | D25: =+D24+D23 -> 1000000 | E25: =+D25+D6+D7 -> 1000000 | H25: Total | I25: =+I24+I23 -> 1509500 | J25: =+I25+I5+I6 -> 1672184.1 | N25: =+N24+N23 -> 1672184.1 | P25: =+W25 -> 1 | R25: Total | S25: =+S23+S24 -> 1 | T25: =+T23+T24 -> 1 | U25: =+U23+U24 -> 1 | V25: =+V23+V24 -> 1 | W25: =+W23+W24 -> 1 | X25: =+X23+X24 -> 1 | Y25: =+Y24+Y23 -> 1509500 | Z25: =+Z24+Z23 -> 1000000 | AA25: =+AA24+AA23 -> 1509500 | AB25: =+AB24+AB23 -> 1000000
I26: =+I25+D25 -> 2509500 | N26: =+N25/I25-1 -> 0.10777348
I27: =+I26=OPTIMIZER!E27 -> TRUE
H30: U.S. Large Cap (S&P 500) | I30: VOO (Vanguard S&P 500)
H31: U.S. Total Market | I31: VTI (Vanguard Total Stock Market)
H32: Large Cap Growth | I32: QQQ (Invesco QQQ Trust - Nasdaq 100) or VUG (Vanguard Growth ETF - Russell 1000)
H33: U.S. Dividend/Quality | I33: SCHD (Schwab U.S. Dividend Equity ETF) or DGRO (iShares Core Dividend Growth ETF)
H34: U.S. Small Cap | I34: VB (Vanguard Small Cap ETF) or IWM (iShares Russell 2000 ETF)
H35: Developed Markets | I35: VEA (Vanguard FTSE Deveoped Market ETF) or IEFA (iShares Core MSCI EAFE ETF)
H36: Emerging Markets | I36: VWO (Vanguard FTSE Emerging Markets ETF) or IEMG (iShares Core MSCI Emerging Markets ETF)
H37: REITS, Commodities | I37: VNQ ( Vanguard Real Estate ETF) or PDBC (Invesco Optimum Yield Diversified Commodity)
H38: Bonds | I38: Bloomberg Aggregate Bond Index
H39: Crypto | I39: Bitwise 10 Crypto Index

Sheet Long-Term Forecast
B1: =+'Cash Flow'!BE119 -> 2025 | C1: =+'Cash Flow'!BJ119 -> 2030 | D1: =+'Cash Flow'!BO119 -> 2035 | E1: =+'Cash Flow'!BP119 -> 2040 | G1: =+B1 -> 2025 | H1: =+C1 -> 2030 | I1: =+D1 -> 2035 | J1: =+E1 -> 2040
A2: Net Worth
A3: Go Alone | B3: =+'Cash Flow'!BE121 -> 4894245.7 | C3: =+'Cash Flow'!BJ121 -> 6449549.1 | D3: =+'Cash Flow'!BO121 -> 8548634.4 | E3: =+'Cash Flow'!BP121 -> 11420835 | G3: =+B3 -> 4894245.7 | H3: =+C3 -> 6449549.1 | I3: =+D3 -> 8548634.4 | J3: =+E3 -> 11420835
A4: With GURU | B4: =+'Cash Flow'!BE122 -> 4894245.7 | C4: =+'Cash Flow'!BJ122 -> 6449549.1 | D4: =+'Cash Flow'!BO122 -> 8548634.4 | E4: =+'Cash Flow'!BP122 -> 11420835 | G4: =+B4-G3 -> 0 | H4: =+C4-H3 -> 0 | I4: =+D4-I3 -> 0 | J4: =+E4-J3 -> 0
B5: =+B4-B3 -> 0 | C5: =+C4-C3 -> 0 | D5: =+D4-D3 -> 0 | E5: =+E4-E3 -> 0
A6: Investments
A7: Go Alone | B7: =+'Cash Flow'!BE128 -> 2690912 | C7: =+'Cash Flow'!BJ128 -> 3774143.2 | D7: =+'Cash Flow'!BO128 -> 5416397.3 | E7: =+'Cash Flow'!BP128 -> 7828573.3
A8: With GURU | B8: =+'Cash Flow'!BE129 -> 2690912 | C8: =+'Cash Flow'!BJ129 -> 3774143.2 | D8: =+'Cash Flow'!BO129 -> 5416397.3 | E8: =+'Cash Flow'!BP129 -> 7828573.3
B9: =+B8-B7 -> 0 | C9: =+C8-C7 -> 0 | D9: =+D8-D7 -> 0 | E9: =+E8-E7 -> 0
A10: Cash
A11: Go Alone | B11: =+'Cash Flow'!BE135 -> 571499.82 | C11: =+'Cash Flow'!BJ135 -> 941408.55 | D11: =+'Cash Flow'!BO135 -> 1323386.7 | E11: =+'Cash Flow'!BP135 -> 1752259.1
A12: With GURU | B12: =+'Cash Flow'!BE136 -> 571499.82 | C12: =+'Cash Flow'!BJ136 -> 941408.55 | D12: =+'Cash Flow'!BO136 -> 1323386.7 | E12: =+'Cash Flow'!BP136 -> 1752259.1

Sheet Dashboard Style
B4: Net Worth | O4: Projected Cumulative Cash Flow | X4: Cash Management Monitor | AM4: Net worth - fake data
B5: =+Charts!S9 -> 4648384 | O5: =+'MoneyBoard - Key Metrics'!C3 -> 66338.316 | X5: SUFFICIENT FUNDS FOR 12 MONTHS | AM5: 43466 | AN5: 3150000
H6: Assets | K6: Liabilities | X6: Cash required for next 12 months | AD6: =-'MoneyBoard - Key Metrics'!$C$6 -> 129384.79 | AM6: 43617 | AN6: =+AN5*(1+AO6) -> 3465000 | AO6: 0.1
X7: Funds to cover cash need | AD7: =+'MoneyBoard - Key Metrics'!C8 -> 372050 | AM7: 43831 | AN7: =+AN6*(1+AO7) -> 3672900 | AO7: 0.06
H8: Bank | J8: =+OPTIMIZER!AR24 -> 20939.42 | AM8: 43831 | AN8: =+AN7*(1+AO8) -> 3783087 | AO8: 0.03
H9: Money Market Fund | J9: =+OPTIMIZER!AR25 -> 129384.79 | AM9: 44197 | AN9: =+AN8*(1+AO9) -> 3896579.6 | AO9: 0.03
H10: Treasuries | J10: =+OPTIMIZER!AR26 -> 194041.71 | AM10: 44348 | AN10: =+AN9*(1+AO10) -> 3701750.6 | AO10: -0.05
H11: Investments | J11: =+'Model Portfolios'!N25 -> 1672184.1 | AM11: 44562 | AN11: =+AN10*(1+AO11) -> 3516663.1 | AO11: -0.05
H12: Real Estate | J12: =+Charts!Z10 -> 1815000 | AE12: =+'MoneyBoard - Balance Sheet'!C82 -> Chase Total Checking | AH12: =+'MoneyBoard - Balance Sheet'!D82 -> 25050 | AM12: 44713 | AN12: =+AN11*(1+AO12) -> 4044162.6 | AO12: 0.15
H13: Carry | J13: =+Charts!Z7 -> 835000 | AE13: =+'MoneyBoard - Balance Sheet'!C83 -> Citizens Private Banking Checking | AH13: =+'MoneyBoard - Balance Sheet'!D83 -> 107000 | AM13: 44927 | AN13: =+AN12*(1+AO13) -> 4246370.7 | AO13: 0.05
H14: Stock Comp | J14: =+Charts!Z8 -> 80000 | AE14: Total Immediate | AG14: =+'MoneyBoard - Balance Sheet'!D84 -> 132050 | AM14: 45078 | AN14: =+AN13*(1+AO14) -> 4331298.1 | AO14: 0.02
H15: Alternative Inv | J15: =+Charts!Z9 -> 250000 | AM15: 45292 | AN15: =+AN14*(1+AO15) -> 4374611.1 | AO15: 0.01
H16: Retirement Accounts | J16: =+Charts!Z6 -> 1000000 | AM16: 45444 | AN16: =+AN15*(1+AO16) -> 4593341.6 | AO16: 0.05
H17: Total | J17: =SUM(J8:K16) -> 5996550 | AM17: 45658 | AN17: =+Charts!S9 -> 4648384
AM20: Projected monthly cash flow
B21: Taxable Brokerage + Retirement Accounts | O21: Income vs. Expense Projection | AC21: Pre-approved Bank Offerings | AM21: 45658 | AN21: =+Charts!E43 -> -19347.3
B22: =+Charts!AB148 -> 2509500 | H22: 1 Year performance | K22: 0.0432 | AC22: HELOC | AE22: SOFR+200bps | AG22: 0.0618 | AM22: 45689 | AN22: =+Charts!F43 -> -1871.9829 | AP22: 45809 | AQ22: 45839 | AR22: 45870 | AS22: 45901 | AT22: 45931
B23: Current vs. Target Model Portfolio | H23: vs. Index | K23: 0.0384 | P23: 45658 | Q23: 45689 | R23: 45717 | S23: 45748 | T23: 45778 | U23: .. | X23: 45962 | Y23: 45992 | AP23: =+Charts!J28 -> 18910.164 | AQ23: =+Charts!K28 -> 18865.289 | AR23: =+Charts!L28 -> 18842.949 | AS23: =+Charts!M28 -> 18838.034 | AT23: =+Charts!N28 -> 18828.49
O24: Income | P24: =+Charts!E28 -> 19092.12 | Q24: =+Charts!F28 -> 19067.437 | R24: =+Charts!G28 -> 19010.765 | S24: =+Charts!H28 -> 18949.217 | T24: =+Charts!I28 -> 18938.666 | U24: .. | X24: =+Charts!O28 -> 18817.566 | Y24: =+Charts!P28 -> 241147.11 | AC24: Margin Loan | AE24: SOFR+100bps | AG24: 0.0518 | AM24: 45717 | AN24: =+Charts!G43 -> -1928.655 | AP24: =+Charts!J42 -> -21939.42 | AQ24: =+Charts!K42 -> -40439.42 | AR24: =+Charts!L42 -> -35939.42 | AS24: =+Charts!M42 -> -20939.42 | AT24: =+Charts!N42 -> -20939.42
O25: Expenses | P25: =+Charts!E42 -> -38439.42 | Q25: =+Charts!F42 -> -20939.42 | R25: =+Charts!G42 -> -20939.42 | S25: =+Charts!H42 -> -65939.42 | T25: =+Charts!I42 -> -24939.42 | U25: .. | X25: =+Charts!O42 -> -24939.42 | Y25: =+Charts!P42 -> -48392.38 | AM25: 45748 | AN25: =+Charts!H43 -> -46990.203 | AP25: =+SUM(AP23:AP24) -> -3029.2556 | AQ25: =+SUM(AQ23:AQ24) -> -21574.131 | AR25: =+SUM(AR23:AR24) -> -17096.471 | AS25: =+SUM(AS23:AS24) -> -2101.3859 | AT25: =+SUM(AT23:AT24) -> -2110.9303
O26: Net Cash Flow | P26: =+SUM(P24:P25) -> -19347.3 | Q26: =+SUM(Q24:Q25) -> -1871.9829 | R26: =+SUM(R24:R25) -> -1928.655 | S26: =+SUM(S24:S25) -> -46990.203 | T26: =+SUM(T24:T25) -> -6000.7541 | U26: … | X26: =+SUM(X24:X25) -> -6121.8545 | Y26: =+SUM(Y24:Y25) -> 192754.73 | AM26: 45778 | AN26: =+Charts!I43 -> -6000.7541
H27: =+Charts!AA139 -> US Total Market | K27: =+Charts!AB139 -> 779877.58 | AM27: 45809 | AN27: =+Charts!J43 -> -3029.2556
H28: =+Charts!AA140 -> US Large Cap | K28: =+Charts!AB140 -> 535000 | AM28: 45839 | AN28: =+Charts!K43 -> -21574.131
H29: =+Charts!AA141 -> US Small Cap | K29: =+Charts!AB141 -> 323582.23 | AM29: 45870 | AN29: =+Charts!L43 -> -17096.471
H30: =+Charts!AA142 -> US Dividend / Value | K30: =+Charts!AB142 -> 94368.991 | O30: GURU OPTIMIZER | AM30: 45901 | AN30: =+Charts!M43 -> -2101.3859
O31: Cash Optimizer | X31: Investments Optimizer | AM31: 45931 | AN31: =+Charts!N43 -> -2110.9303
O32: =+'MoneyBoard - Key Metrics'!A10 -> Cash Excess/Deficit Positon | T32: =+'MoneyBoard - Key Metrics'!C10 -> 162684.07 | X32: =+'MoneyBoard - Key Metrics'!A15 -> Total Cash You Should Invest Today (A+B): | AE32: =+'MoneyBoard - Key Metrics'!C15 -> 385649.51 | AM32: 45962 | AN32: =+Charts!O43 -> -6121.8545
O33: =+'MoneyBoard - Key Metrics'!A11 -> Identified Additional Cash Income / Year | T33: =+'MoneyBoard - Key Metrics'!C11 -> 7207.434 | AF33: =+'MoneyBoard - Key Metrics'!D15 -> 15% increase to investments | AM33: 45992 | AN33: =+Charts!P43 -> 192754.73
V34: =+'MoneyBoard - Key Metrics'!D11 -> 11% increase to your cash flow | X34: =+'MoneyBoard - Key Metrics'!A13 -> A: Cash in Investment Accounts to be Deployed | AE34: =+'MoneyBoard - Key Metrics'!C13 -> 222965.43
X35: =+'MoneyBoard - Key Metrics'!A14 -> B: Excess cash to be reallocate to investments | AE35: =+'MoneyBoard - Key Metrics'!C14 -> 162684.07
O36: Actions Here | X36: Actions Here | AM36: Projected cumulative cashflow
AM38: 45658 | AN38: =+Charts!E47 -> -19347.3
AM39: 45689 | AN39: =+Charts!F47 -> -21219.283
AM41: 45717 | AN41: =+Charts!G47 -> -23147.938
AM42: 45748 | AN42: =+Charts!H47 -> -70138.141
AC43: Tracking Medium-Term Goal | AM43: 45778 | AN43: =+Charts!I47 -> -76138.895
AC44: Current savings | AE44: =+OPTIMIZER!G26 -> 194041.71 | AG44: =+AE44/'Rent vs. Buy'!C17 -> 0.53917325 | AM44: 45809 | AN44: =+Charts!J47 -> -79168.151
AC45: Goal: | AF45: Purchase new primary residence (+$1-2million) | AM45: 45839 | AN45: =+Charts!K47 -> -100742.28
AM46: 45870 | AN46: =+Charts!L47 -> -117838.75
AC47: Target savings | AH47: =+'Rent vs. Buy'!C17 -> 359887.5 | AM47: 45901 | AN47: =+Charts!M47 -> -119940.14
...

Sheet Money Movement
B1: Immediate
E2: =+'Cash Flow'!BE75 -> January | F2: =+'Cash Flow'!BF75 -> February | G2: =+'Cash Flow'!BG75 -> March | H2: =+'Cash Flow'!BH75 -> April | I2: =+'Cash Flow'!BI75 -> May | J2: =+'Cash Flow'!BJ75 -> June | K2: =+'Cash Flow'!BK75 -> July | L2: =+'Cash Flow'!BL75 -> August | ... P2: =+'Cash Flow'!BP75 -> December
B3: Status Quo | E3: =+'Cash Flow'!BE77 -> 132050 | F3: =+'Cash Flow'!BF77 -> 132050 | G3: =+'Cash Flow'!BG77 -> 132050 | H3: =+'Cash Flow'!BH77 -> 132050 | I3: =+'Cash Flow'!BI77 -> 132050 | J3: =+'Cash Flow'!BJ77 -> 132050 | K3: =+'Cash Flow'!BK77 -> 132050 | L3: =+'Cash Flow'!BL77 -> 132050 | ... P3: =+'Cash Flow'!BP77 -> 179141.39
B4: GURU | E4: =+'Cash Flow'!BE78 -> 20939.42 | F4: =+'Cash Flow'!BF78 -> 20939.42 | G4: =+'Cash Flow'!BG78 -> 65939.42 | H4: =+'Cash Flow'!BH78 -> 24939.42 | I4: =+'Cash Flow'!BI78 -> 21939.42 | J4: =+'Cash Flow'!BJ78 -> 40439.42 | K4: =+'Cash Flow'!BK78 -> 35939.42 | L4: =+'Cash Flow'!BL78 -> 20939.42 | ... P4: =+'Cash Flow'!BP78 -> 38439.574
B6: Short Term Accounts
E7: =+'Cash Flow'!BE81 -> January | F7: =+'Cash Flow'!BF81 -> February | G7: =+'Cash Flow'!BG81 -> March | H7: =+'Cash Flow'!BH81 -> April | I7: =+'Cash Flow'!BI81 -> May | J7: =+'Cash Flow'!BJ81 -> June | K7: =+'Cash Flow'!BK81 -> July | L7: =+'Cash Flow'!BL81 -> August | ... P7: =+'Cash Flow'!BP81 -> December
B8: =+B3 -> Status Quo | E8: =+'Cash Flow'!BE83 -> 220374.11 | F8: =+'Cash Flow'!BF83 -> 218620.68 | G8: =+'Cash Flow'!BG83 -> 216850.28 | H8: =+'Cash Flow'!BH83 -> 170077.02 | I8: =+'Cash Flow'!BI83 -> 164264.54 | J8: =+'Cash Flow'!BJ83 -> 161409.55 | K8: =+'Cash Flow'!BK83 -> 140047.52 | L8: =+'Cash Flow'!BL83 -> 123165.92 | ... P8: =+'Cash Flow'!BP83 -> 253553.99
B9: GURU | E9: =+'Cash Flow'!BE84 -> 109758.9 | F9: =+'Cash Flow'!BF84 -> 107911.6 | G9: =+'Cash Flow'!BG84 -> 61039.621 | H9: =+'Cash Flow'!BH84 -> 55110.966 | I9: =+'Cash Flow'!BI84 -> 52120.762 | J9: =+'Cash Flow'!BJ84 -> 30620.008 | K9: =+'Cash Flow'!BK84 -> 13590.753 | L9: =+'Cash Flow'!BL84 -> 11516.622 | ... P9: =+'Cash Flow'!BP84 -> 129388.68
B11: Medium-Term Accounts
E12: =+'Cash Flow'!BE87 -> January | F12: =+'Cash Flow'!BF87 -> February | G12: =+'Cash Flow'!BG87 -> March | H12: =+'Cash Flow'!BH87 -> April | I12: =+'Cash Flow'!BI87 -> May | J12: =+'Cash Flow'!BJ87 -> June | K12: =+'Cash Flow'!BK87 -> July | L12: =+'Cash Flow'!BL87 -> August | ... P12: =+'Cash Flow'!BP87 -> December
B13: =+B8 -> Status Quo | E13: =+'Cash Flow'!BE89 -> 135000 | F13: =+'Cash Flow'!BF89 -> 135288.84 | G13: =+'Cash Flow'!BG89 -> 135578.31 | H13: =+'Cash Flow'!BH89 -> 135868.39 | I13: =+'Cash Flow'!BI89 -> 136159.09 | J13: =+'Cash Flow'!BJ89 -> 136450.41 | K13: =+'Cash Flow'!BK89 -> 136742.36 | L13: =+'Cash Flow'!BL89 -> 137034.93 | ... P13: =+'Cash Flow'!BP89 -> 138211.49
B14: GURU | E14: =+'Cash Flow'!BE90 -> 135000 | F14: =+'Cash Flow'!BF90 -> 135288.84 | G14: =+'Cash Flow'!BG90 -> 135578.31 | H14: =+'Cash Flow'!BH90 -> 135868.39 | I14: =+'Cash Flow'!BI90 -> 136159.09 | J14: =+'Cash Flow'!BJ90 -> 136450.41 | K14: =+'Cash Flow'!BK90 -> 136742.36 | L14: =+'Cash Flow'!BL90 -> 137034.93 | ... P14: =+'Cash Flow'!BP90 -> 138211.49
B16: Long-Term Accounts
E17: =+'Cash Flow'!BE93 -> January | F17: =+'Cash Flow'!BF93 -> February | G17: =+'Cash Flow'!BG93 -> March | H17: =+'Cash Flow'!BH93 -> April | I17: =+'Cash Flow'!BI93 -> May | J17: =+'Cash Flow'!BJ93 -> June | K17: =+'Cash Flow'!BK93 -> July | L17: =+'Cash Flow'!BL93 -> August | ... P17: =+'Cash Flow'!BP93 -> December
B18: =+B13 -> Status Quo | E18: =+'Cash Flow'!BE95 -> 2524138.8 | F18: =+'Cash Flow'!BF95 -> 2538862.9 | G18: =+'Cash Flow'!BG95 -> 2553672.9 | H18: =+'Cash Flow'!BH95 -> 2568569.4 | I18: =+'Cash Flow'!BI95 -> 2583552.7 | J18: =+'Cash Flow'!BJ95 -> 2598623.4 | K18: =+'Cash Flow'!BK95 -> 2613782 | L18: =+'Cash Flow'!BL95 -> 2629029.1 | ... P18: =+'Cash Flow'!BP95 -> 2690912
B19: GURU | E19: =+'Cash Flow'!BE96 -> 2524138.8 | F19: =+'Cash Flow'!BF96 -> 2538862.9 | G19: =+'Cash Flow'!BG96 -> 2553672.9 | H19: =+'Cash Flow'!BH96 -> 2568569.4 | I19: =+'Cash Flow'!BI96 -> 2583552.7 | J19: =+'Cash Flow'!BJ96 -> 2598623.4 | K19: =+'Cash Flow'!BK96 -> 2613782 | L19: =+'Cash Flow'!BL96 -> 2629029.1 | ... P19: =+'Cash Flow'!BP96 -> 2690912
B21: Net Worth
E22: =+'Cash Flow'!BE99 -> January | F22: =+'Cash Flow'!BF99 -> February | G22: =+'Cash Flow'!BG99 -> March | H22: =+'Cash Flow'!BH99 -> April | I22: =+'Cash Flow'!BI99 -> May | J22: =+'Cash Flow'!BJ99 -> June | K22: =+'Cash Flow'!BK99 -> July | L22: =+'Cash Flow'!BL99 -> August | ... P22: =+'Cash Flow'!BP99 -> December
B23: =+B18 -> Status Quo | E23: =+'Cash Flow'!BE101 -> 4643396.8 | F23: =+'Cash Flow'!BF101 -> 4656656.4 | G23: =+'Cash Flow'!BG101 -> 4669985.5 | H23: =+'Cash Flow'!BH101 -> 4638398.7 | I23: =+'Cash Flow'!BI101 -> 4647860.3 | J23: =+'Cash Flow'!BJ101 -> 4660367.3 | K23: =+'Cash Flow'!BK101 -> 4654455.9 | L23: =+'Cash Flow'!BL101 -> 4653113.9 | ... P23: =+'Cash Flow'!BP101 -> 4893652.8
B24: GURU | E24: =+'Cash Flow'!BE102 -> 4643396.8 | F24: =+'Cash Flow'!BF102 -> 4656656.4 | G24: =+'Cash Flow'!BG102 -> 4669985.5 | H24: =+'Cash Flow'!BH102 -> 4638398.7 | I24: =+'Cash Flow'!BI102 -> 4647860.3 | J24: =+'Cash Flow'!BJ102 -> 4660367.3 | K24: =+'Cash Flow'!BK102 -> 4654455.9 | L24: =+'Cash Flow'!BL102 -> 4653113.9 | ... P24: =+'Cash Flow'!BP102 -> 4893652.8
E32: =E2 -> January | F32: =F2 -> February | G32: =G2 -> March | H32: =H2 -> April | I32: =I2 -> May | J32: =J2 -> June | K32: =K2 -> July | L32: =L2 -> August | ... P32: =P2 -> December
B33: Plus: Income Allocation to Immediate | E33: =+'Cash Flow'!BE108 -> 18813.53 | F33: =+'Cash Flow'!BF108 -> 18813.53 | G33: =+'Cash Flow'!BG108 -> 18813.53 | H33: =+'Cash Flow'!BH108 -> 18813.53 | I33: =+'Cash Flow'!BI108 -> 18813.53 | J33: =+'Cash Flow'!BJ108 -> 18813.53 | K33: =+'Cash Flow'!BK108 -> 18813.53 | L33: =+'Cash Flow'!BL108 -> 18813.53 | ... P33: =+'Cash Flow'!BP108 -> 38439.42
B34: Less: Expenses | E34: =+'Cash Flow'!BE115 -> -38439.42 | F34: =+'Cash Flow'!BF115 -> -20939.42 | G34: =+'Cash Flow'!BG115 -> -20939.42 | H34: =+'Cash Flow'!BH115 -> -65939.42 | I34: =+'Cash Flow'!BI115 -> -24939.42 | J34: =+'Cash Flow'!BJ115 -> -21939.42 | K34: =+'Cash Flow'!BK115 -> -40439.42 | L34: =+'Cash Flow'!BL115 -> -35939.42 | ... P34: =+'Cash Flow'!BP115 -> -48392.38
B35: Plus: Cash Moved from Short-Term Into Immediate | E35: =+'Cash Flow'!BS78-E36 -> 19625.89 | F35: =+'Cash Flow'!BT78-F36 -> 2125.8026 | G35: =+'Cash Flow'!BU78-G36 -> 47125.803 | H35: =+'Cash Flow'!BV78-H36 -> 6125.7084 | I35: =+'Cash Flow'!BW78-I36 -> 3125.7 | J35: =+'Cash Flow'!BX78-J36 -> 21625.792 | K35: =+'Cash Flow'!BY78-K36 -> 17125.76 | L35: =+'Cash Flow'!BZ78-L36 -> 2125.7304 | ... P35: =+'Cash Flow'!CD78-P36 -> 0
B36: Plus: Cash Moved from Medium-Term Into Immediate | E36: =+'Cash Flow'!BS85 -> 0 | F36: =+'Cash Flow'!BT85 -> 0 | G36: =+'Cash Flow'!BU85 -> 0 | H36: =+'Cash Flow'!BV85 -> 0 | I36: =+'Cash Flow'!BW85 -> 0 | J36: =+'Cash Flow'!BX85 -> 0 | K36: =+'Cash Flow'!BY85 -> 0 | L36: =+'Cash Flow'!BZ85 -> 0 | ... P36: =+'Cash Flow'!CD85 -> 0
B37: Plus: After-Tax Interest Income | E37: 0 | F37: =+'Cash Flow'!BS103 -> 0.087719995 | G37: =+'Cash Flow'!BT103 -> 0.087720179 | H37: =+'Cash Flow'!BU103 -> 0.1819778 | I37: =+'Cash Flow'!BV103 -> 0.19035645 | J37: =+'Cash Flow'!BW103 -> 0.098193463 | K37: =+'Cash Flow'!BX103 -> 0.13065978 | L37: =+'Cash Flow'!BY103 -> 0.15998444 | M37: =+'Cash Flow'!BZ103 -> 0.11913954 | ... P37: =+'Cash Flow'!CC103 -> 0.153602
B38: Immediate | C38: =+OPTIMIZER!AV24 -> CIT Money Market Fund | D38: =+OPTIMIZER!G24 -> 20939.42 | E38: =+E4 -> 20939.42 | F38: =+F4 -> 20939.42 | G38: =+G4 -> 65939.42 | H38: =+H4 -> 24939.42 | I38: =+I4 -> 21939.42 | J38: =+J4 -> 40439.42 | K38: =+K4 -> 35939.42 | L38: =+L4 -> 20939.42 | ... P38: =+P4 -> 38439.574
B40: Plus: Income Allocation to Short-Term | E40: =+'Cash Flow'!BS91 -> 0 | F40: =+'Cash Flow'!BT91 -> 0 | G40: =+'Cash Flow'!BU91 -> 0 | H40: =+'Cash Flow'!BV91 -> 0 | I40: =+'Cash Flow'!BW91 -> 0 | J40: =+'Cash Flow'!BX91 -> 0 | K40: =+'Cash Flow'!BY91 -> 0 | L40: =+'Cash Flow'!BZ91 -> 0 | ... P40: =+'Cash Flow'!CD91 -> 129384.79
B41: Less: Cash Moved from Short-Term Into Immediate | E41: =-E35 -> -19625.89 | F41: =-F35 -> -2125.8026 | G41: =-G35 -> -47125.803 | H41: =-H35 -> -6125.7084 | I41: =-I35 -> -3125.7 | J41: =-J35 -> -21625.792 | K41: =-K35 -> -17125.76 | L41: =-L35 -> -2125.7304 | ... P41: =-P35 -> 0
B42: Plus: After-Tax Interest Income | E42: 0 | F42: =+'Cash Flow'!BS110 -> 278.50276 | G42: =+'Cash Flow'!BT110 -> 253.81978 | H42: =+'Cash Flow'!BU110 -> 197.05337 | I42: =+'Cash Flow'!BV110 -> 135.49652 | J42: =+'Cash Flow'!BW110 -> 125.03808 | K42: =+'Cash Flow'!BX110 -> 96.50414 | L42: =+'Cash Flow'!BY110 -> 51.599503 | M42: =+'Cash Flow'!BZ110 -> 29.299722 | ... P42: =+'Cash Flow'!CC110 -> 3.8822881
B43: Short-Term | C43: =+OPTIMIZER!AV25 -> JPMorgan 100% Treasuries Money Market Fund | D43: =+OPTIMIZER!G25 -> 129384.79 | E43: =+E9 -> 109758.9 | F43: =+F9 -> 107911.6 | G43: =+G9 -> 61039.621 | H43: =+H9 -> 55110.966 | I43: =+I9 -> 52120.762 | J43: =+J9 -> 30620.008 | K43: =+K9 -> 13590.753 | L43: =+L9 -> 11516.622 | ... P43: =+P9 -> 129388.68
B45: Plus: Income Allocation to Immediate | E45: =+'Cash Flow'!BS97 -> 0 | F45: =+'Cash Flow'!BT97 -> 0 | G45: =+'Cash Flow'!BU97 -> 0 | H45: =+'Cash Flow'!BV97 -> 0 | I45: =+'Cash Flow'!BW97 -> 0 | J45: =+'Cash Flow'!BX97 -> 0 | K45: =+'Cash Flow'!BY97 -> 0 | L45: =+'Cash Flow'!BZ97 -> 0 | ... P45: =+'Cash Flow'!CD97 -> 67629.96
B46: Less: Cash Moved from Medium-Term to Immediate | E46: =-E36 -> 0 | F46: =-F36 -> 0 | G46: =-G36 -> 0 | H46: =-H36 -> 0 | I46: =-I36 -> 0 | J46: =-J36 -> 0 | K46: =-K36 -> 0 | L46: =-L36 -> 0 | ... P46: =-P36 -> 0
B47: Plus: After-Tax Interest Income | E47: 0 | F47: =+'Cash Flow'!BS116 -> 288.84375 | G47: =+'Cash Flow'!BT116 -> 289.46176 | H47: =+'Cash Flow'!BU116 -> 290.08108 | I47: =+'Cash Flow'!BV116 -> 290.70174 | J47: =+'Cash Flow'!BW116 -> 291.32372 | K47: =+'Cash Flow'!BX116 -> 291.94703 | L47: =+'Cash Flow'!BY116 -> 292.57167 | M47: =+'Cash Flow'!BZ116 -> 293.19765 | ... P47: =+'Cash Flow'!CC116 -> 295.08365
B48: Medium-Term | C48: =+OPTIMIZER!AV26 -> 1 Year Treasuries + 2028 Muni Bonds | D48: =+OPTIMIZER!G26 -> 194041.71 | E48: =+E14 -> 135000 | F48: =+F14 -> 135288.84 | G48: =+G14 -> 135578.31 | H48: =+H14 -> 135868.39 | I48: =+I14 -> 136159.09 | J48: =+J14 -> 136450.41 | K48: =+K14 -> 136742.36 | L48: =+L14 -> 137034.93 | ... P48: =+P14 -> 138211.49
B50: Long-Term ( Brokerage & Retirement) | C50: =+OPTIMIZER!AV27 -> Growth equity market ETFs | D50: =+OPTIMIZER!G27 -> 2672184.1 | E50: =+E19 -> 2524138.8 | F50: =+F19 -> 2538862.9 | G50: =+G19 -> 2553672.9 | H50: =+H19 -> 2568569.4 | I50: =+I19 -> 2583552.7 | J50: =+J19 -> 2598623.4 | K50: =+K19 -> 2613782 | L50: =+L19 -> 2629029.1 | ... P50: =+P19 -> 2690912
B52: Total Net Worth | E52: =+E24 -> 4643396.8 | F52: =+F24 -> 4656656.4 | G52: =+G24 -> 4669985.5 | H52: =+H24 -> 4638398.7 | I52: =+I24 -> 4647860.3 | J52: =+J24 -> 4660367.3 | K52: =+K24 -> 4654455.9 | L52: =+L24 -> 4653113.9 | ... P52: =+P24 -> 4893652.8

Sheet Cash Flow Walk
B1: 4Q2024 | C1: 1Q2025 | D1: 2Q2025 | E1: 3Q2025 | F1: 4Q2025
B2: December | C2: =+'Cash Flow'!G5 -> March | D2: =+'Cash Flow'!J5 -> June | E2: =+'Cash Flow'!M5 -> September | F2: =+'Cash Flow'!P5 -> December
A3: Beginning | C3: =+B9 -> 193661.05 | D3: =+C9 -> 170513.11 | E3: =+D9 -> 114492.9 | F3: =+E9 -> 73720.909
A4: Income | C4: =SUM('Cash Flow'!$E$16:$G$16) -> 57170.322 | D4: =SUM('Cash Flow'!$H$16:$J$16) -> 56798.047 | E4: =SUM('Cash Flow'!$K$16:$M$16) -> 56546.272 | F4: =SUM('Cash Flow'!$N$16:$P$16) -> 279157.94
A5: Core Expenses | C5: =+C12-SUM(C6:C8) -> -62818.26 | D5: =+D12-SUM(D6:D8) -> -67818.26 | E5: =+E12-SUM(E6:E8) -> -64818.26 | F5: =+F12-SUM(F6:F8) -> -74574.62
A6: Property Taxes | C6: =SUM('Cash Flow'!$E$18:$G$18)+SUM('Cash Flow'!$E$27:$G$27) -> -17500 | D6: =SUM('Cash Flow'!$H$18:$J$18)+SUM('Cash Flow'!$H$27:$J$27) -> 0 | E6: =SUM('Cash Flow'!$K$18:$M$18)+SUM('Cash Flow'!$K$27:$M$27) -> -17500 | F6: =SUM('Cash Flow'!$N$18:$P$18)+SUM('Cash Flow'!$N$27:$P$27) -> -4696.6
A7: Tuition | C7: =SUM('Cash Flow'!$E$50:$G$50) -> 0 | D7: =SUM('Cash Flow'!$H$50:$J$50) -> -15000 | E7: =SUM('Cash Flow'!$K$50:$M$50) -> -15000 | F7: =SUM('Cash Flow'!$N$50:$P$50) -> -15000
A8: Taxes | C8: =SUM('Cash Flow'!$E$62:$G$62) -> 0 | D8: =SUM('Cash Flow'!$H$62:$J$62) -> -30000 | E8: =SUM('Cash Flow'!$K$62:$M$62) -> 0 | F8: =SUM('Cash Flow'!$N$62:$P$62) -> 0
A9: Ending | B9: =+'Cash Flow'!D67 -> 193661.05 | C9: =SUM(C3:C8) -> 170513.11 | D9: =SUM(D3:D8) -> 114492.9 | E9: =SUM(E3:E8) -> 73720.909 | F9: =SUM(F3:F8) -> 259999.36
A12: Total Expenses | C12: =SUM('Cash Flow'!$E$63:$G$63) -> -80318.26 | D12: =SUM('Cash Flow'!$H$63:$J$63) -> -112818.26 | E12: =SUM('Cash Flow'!$K$63:$M$63) -> -97318.26 | F12: =SUM('Cash Flow'!$N$63:$P$63) -> -94271.22 | U12: 1000
C14: =C1 -> 1Q2025 | G14: =D1 -> 2Q2025 | K14: =E1 -> 3Q2025 | O14: =+F1 -> 4Q2025
B15: Beginning | C15: Income | D15: Core Expenses | E15: One-Time Expenses | F15: 45747 | G15: Income | H15: Core Expenses | I15: One-Time Expenses | J15: 45838 | K15: Income | L15: Core Expenses | M15: One-Time Expenses | N15: 45930 | O15: Income | P15: Core Expenses | Q15: One-Time Expenses | R15: 46022 | T15: Beginning 1/1/25 | U15: Annual Income | V15: Core Expenses | W15: One-Time Expenses | X15: Ending Cash 12/31/2025
A16: Total | B16: =+B9 -> 193661.05 | C16: =+C3 -> 193661.05 | D16: =+C16+C17-D17 -> 188013.11 | E16: =D16-E17 -> 170513.11 | F16: =E16 -> 170513.11 | G16: =+D3 -> 170513.11 | H16: =+G16+G17-H17 -> 159492.9 | I16: =H16-I17 -> 114492.9 | J16: =I16 -> 114492.9 | K16: =+E3 -> 114492.9 | L16: =+K16+K17-L17 -> 106220.91 | M16: =L16-M17 -> 73720.909 | N16: =M16 -> 73720.909 | O16: =+F3 -> 73720.909 | P16: =+O16+O17-P17 -> 279695.96 | Q16: =P16-Q17 -> 259999.36 | R16: =Q16 -> 259999.36 | T16: =(+B16)/1000 -> 193.66105 | U16: =+T16 -> 193.66105 | V16: =+U16+U17-V17 -> 374.69596 | W16: =V16-W17 -> 259.99936 | X16: =W16 -> 259.99936
C17: =+C4 -> 57170.322 | D17: =-C5 -> 62818.26 | E17: =-C6-C7-C8 -> 17500 | G17: =+D4 -> 56798.047 | H17: =-D5 -> 67818.26 | I17: =-D6-D7-D8 -> 45000 | K17: =+E4 -> 56546.272 | L17: =-E5 -> 64818.26 | M17: =-E6-E7-E8 -> 32500 | O17: =+F4 -> 279157.94 | P17: =-F5 -> 74574.62 | Q17: =-F6-F7-F8 -> 19696.6 | U17: =(+C17+G17+K17+O17)/1000 -> 451.06432 | V17: =(+D17+H17+L17+P17)/1000 -> 270.0294 | W17: =(+E17+I17+M17+Q17)/1000 -> 114.6966
A19: Data Label | C19: =+C17 -> 57170.322 | D19: =-D17 -> -62818.26 | E19: =-E17 -> -17500 | G19: =+G17 -> 56798.047 | H19: =-H17 -> -67818.26 | I19: =-I17 -> -45000 | K19: =+K17 -> 56546.272 | L19: =-L17 -> -64818.26 | M19: =-M17 -> -32500 | O19: =+O17 -> 279157.94 | P19: =-P17 -> -74574.62 | Q19: =-Q17 -> -19696.6 | U19: =(+C19+G19+K19+O19)/1000 -> 451.06432 | V19: =-V17 -> -270.0294 | W19: =-W17 -> -114.6966

Sheet MoneyBoard - Balance Sheet
C1: SUMMARY NET WORTH / BALANCE SHEET
C3: Category | D3: Current Balance | H3: % of Total
A4: Highly liquid | C4: =+'Balance Sheet'!A14 -> Cash | D4: =+'Balance Sheet'!B14 -> 372050 | H4: =+D4/$D$11 -> 0.062044009
A5: Liquid (tax inefficent) | C5: Liquid Investments (Taxable Brokerage) | D5: =+'Balance Sheet'!B19 -> 1644500 | H5: =+D5/$D$11 -> 0.27424102
A6: Liquid (time to sell) | C6: =+'Balance Sheet'!A33 -> Real Estate | D6: =+'Balance Sheet'!B33 -> 1815000 | H6: =+D6/$D$11 -> 0.30267404
A7: Commited and includes penalties for liquidity | C7: =+'Balance Sheet'!A22 -> Alternative Assets | D7: =+'Balance Sheet'!B22 -> 250000 | H7: =+D7/$D$11 -> 0.041690639 | M7: Total Assets | N7: =+D11 -> 5996550
C8: =+'Balance Sheet'!A26 -> Carry | D8: =+'Balance Sheet'!B26 -> 835000 | H8: =+D8/$D$11 -> 0.13924673 | M8: Less: Total Liabilities | N8: =-D19 -> -1348166
C9: =+'Balance Sheet'!A28 -> Stock Compensation | D9: =+'Balance Sheet'!B28 -> 80000 | H9: =+D9/$D$11 -> 0.013341004 | M9: Your Net Worth: | N9: =SUM(N7:N8) -> 4648384
C10: =+'Balance Sheet'!A36 -> Retirement | D10: =+'Balance Sheet'!B36 -> 1000000 | H10: =+D10/$D$11 -> 0.16676256 | M10: (Assets - Liabilities)
C11: =+'Balance Sheet'!A37 -> Total Assets | D11: =+'Balance Sheet'!B37 -> 5996550 | E11: =+D11=SUM(D4:D10) -> TRUE | H11: =+D11/$D$11 -> 1
C13: Category | D13: Current Balance | H13: % of Total
C14: =+'Balance Sheet'!A43 -> Credit Cards / Lines of Credit | D14: =+'Balance Sheet'!B43 -> 11466.03 | H14: =+D14/$D$19 -> 0.0085049094
C15: =+'Balance Sheet'!A47 -> Student Loans | D15: =+'Balance Sheet'!B47 -> 69700 | H15: =+D15/$D$19 -> 0.051699864
C16: =+'Balance Sheet'!A50 -> Mortgages | D16: =+'Balance Sheet'!B50 -> 1092000 | H16: =+D16/$D$19 -> 0.80998926
C17: =+'Balance Sheet'!A51 -> Professional Loans (Private Equity) | D17: =+'Balance Sheet'!B51 -> 125000 | H17: =+D17/$D$19 -> 0.09271855
C18: =+'Balance Sheet'!A54 -> Remaining Capital Commitment | D18: =+'Balance Sheet'!B54 -> 50000 | H18: =+D18/$D$19 -> 0.03708742
C19: =+'Balance Sheet'!A55 -> Total Liabilities | D19: =+'Balance Sheet'!B55 -> 1348166 | E19: =SUM(D14:D18)=D19 -> TRUE | H19: =+D19/$D$19 -> 1
C25: DETAILED BALANCE SHEET
C27: Asset Category | D27: Current Balance | E27: Return | H27: Comments
C28: ='Balance Sheet'!A7 -> Chase Total Checking | D28: ='Balance Sheet'!B7 -> 25050 | E28: ='Balance Sheet'!E7 -> 0.0005 | H28: Main Account
C29: ='Balance Sheet'!A8 -> Citizens Private Banking Checking | D29: ='Balance Sheet'!B8 -> 107000 | E29: ='Balance Sheet'!E8 -> 0 | H29: Excess
C30: ='Balance Sheet'!A9 -> Checking Bank Accounts | D30: ='Balance Sheet'!B9 -> 132050 | E30: ='Balance Sheet'!E9 -> 9.4850435e-05
C31: ='Balance Sheet'!A10 -> Citizens Private Bank Money Market | D31: ='Balance Sheet'!B10 -> 225000 | E31: ='Balance Sheet'!E10 -> 0.0365 | H31: Excess
C32: ='Balance Sheet'!A11 -> CapitalOne 360 Perf Savings | D32: ='Balance Sheet'!B11 -> 15000 | E32: ='Balance Sheet'!E11 -> 0.0378
C33: ='Balance Sheet'!A12 -> [Savings 3 Placeholder] | D33: ='Balance Sheet'!B12 -> 0 | E33: ='Balance Sheet'!E12 -> 0
C34: ='Balance Sheet'!A13 -> Savings & Money Market Accounts | D34: ='Balance Sheet'!B13 -> 240000 | E34: ='Balance Sheet'!E13 -> 0.03658125
C35: ='Balance Sheet'!A14 -> Cash | D35: ='Balance Sheet'!B14 -> 372050 | E35: ='Balance Sheet'!E14 -> 0.0236313
C36: ='Balance Sheet'!A15 -> Treasuries | D36: ='Balance Sheet'!B15 -> 135000 | E36: ='Balance Sheet'!E15 -> 0.0395
C37: ='Balance Sheet'!A16 -> ETFs/ Mutual Funds | D37: ='Balance Sheet'!B16 -> 1201688.6 | E37: ='Balance Sheet'!E16 -> 0
C38: ='Balance Sheet'!A17 -> Crypto | D38: ='Balance Sheet'!B17 -> 9500 | E38: ='Balance Sheet'!E17 -> 0
C39: ='Balance Sheet'!A18 -> Single Stock | D39: ='Balance Sheet'!B18 -> 298311.43 | E39: [Return]
C40: ='Balance Sheet'!A19 -> Fidelity Taxable Brokerage | D40: ='Balance Sheet'!B19 -> 1644500 | E40: [Return]
C41: ='Balance Sheet'!A20 -> Private Equity Fund 1 | D41: ='Balance Sheet'!B20 -> 75000 | E41: [Return]
C42: ='Balance Sheet'!A21 -> Private Equity Fund 2 | D42: ='Balance Sheet'!B21 -> 175000 | E42: [Return]
C43: ='Balance Sheet'!A22 -> Alternative Assets | D43: ='Balance Sheet'!B22 -> 250000 | E43: [Return]
C44: ='Balance Sheet'!A23 -> Investments | D44: ='Balance Sheet'!B23 -> 1894500 | E44: [Return]
C45: ='Balance Sheet'!A24 -> Carry Private Equity Fund 1 | D45: ='Balance Sheet'!B24 -> 325000 | E45: [Return]
C46: ='Balance Sheet'!A25 -> Carry Private Equity Fund 2 | D46: ='Balance Sheet'!B25 -> 510000 | E46: [Return]
C47: ='Balance Sheet'!A26 -> Carry | D47: ='Balance Sheet'!B26 -> 835000 | E47: [Return]
C48: ='Balance Sheet'!A27 -> Goldman RSUs | D48: ='Balance Sheet'!B27 -> 80000 | E48: [Return]
...

Sheet Charts
A2: DASHBOARD OUTPUT [WORK IN PROGRESS]
A3: Assets | L3: Liabilities
V4: THESE COLUMNS HAVE DATA FOR THE CHARTS TO THE LEFT
V5: =A3 -> Assets
V6: Retirement Assets | Z6: =(('Balance Sheet'!B36)/1000)*1000 -> 1000000 | AE6: =L3 -> Liabilities
V7: Private Equity Carry | Z7: =+'Balance Sheet'!B24+'Balance Sheet'!B25 -> 835000 | AE7: Credit Cards / Line of Credits | AG7: =(('Balance Sheet'!B43)/1000)*1000 -> 11466.03
S8: Net Worth | V8: Stock Compensation | Z8: =+'Balance Sheet'!B28 -> 80000 | AE8: Student Debt | AG8: =('Balance Sheet'!B47) -> 69700
S9: ='Balance Sheet'!B56 -> 4648384 | V9: Alternative Asset Investments | Z9: =+'Balance Sheet'!B22 -> 250000 | AE9: Mortgages | AG9: =(('Balance Sheet'!B50)/1000)*1000 -> 1092000
V10: Real Estate | Z10: =(('Balance Sheet'!B33)/1000)*1000 -> 1815000 | AE10: Professional / PE Loans | AG10: =+'Balance Sheet'!B51 -> 125000
V11: Liquid Investments | Z11: =+'Balance Sheet'!B15+'Balance Sheet'!B16+'Balance Sheet'!B17+'Balance Sheet'!B18 -> 1644500 | AE11: Remaining Capital Commitment | AG11: =+'Balance Sheet'!B54 -> 50000
V12: Cash | Z12: =(('Balance Sheet'!B14)/1000)*1000 -> 372050 | AE12: Total | AG12: =(SUM(AG7:AG11)) -> 1348166
V13: Total | Z13: =SUM(Z6:Z12) -> 5996550 | AA13: =+AA6+SUM(Z6:Z12) -> 5996550 | AG13: =+AG12='Balance Sheet'!B55 -> TRUE
V14: Check | Z14: =+Z13='Balance Sheet'!B37 -> TRUE
V17: Cash_Treasuries | Z17: =+'Balance Sheet'!B14+'Balance Sheet'!B15 -> 507050
B19: Return / Yield: | C19: [TBD] | E19: [TBD] | F19: [TBD] | G19: [TBD] | H19: [TBD] | I19: [TBD] | K19: Cost: | M19: [TBD] | N19: [TBD] | O19: [TBD] | Q19: [TBD]
A22: Cash Flow Prediction Model
D24: Actual | E24: Forecast | Q24: Next 12
D25: =+'Cash Flow'!D5 -> December | E25: =+'Cash Flow'!E5 -> January | F25: =+'Cash Flow'!F5 -> February | G25: =+'Cash Flow'!G5 -> March | H25: =+'Cash Flow'!H5 -> April | I25: =+'Cash Flow'!I5 -> May | J25: =+'Cash Flow'!J5 -> June | K25: =+'Cash Flow'!K5 -> July | ... P25: =+'Cash Flow'!P5 -> December | Q25: Months
A26: =+'Cash Flow'!A10 -> Compensation | D26: =+SUMIF('Cash Flow'!$A$6:$A$67,$A26,'Cash Flow'!D$6:D$67) -> 235454.17 | E26: =+SUMIF('Cash Flow'!$A$6:$A$67,$A26,'Cash Flow'!E$6:E$67) -> 18813.53 | F26: =+SUMIF('Cash Flow'!$A$6:$A$67,$A26,'Cash Flow'!F$6:F$67) -> 18813.53 | G26: =+SUMIF('Cash Flow'!$A$6:$A$67,$A26,'Cash Flow'!G$6:G$67) -> 18813.53 | H26: =+SUMIF('Cash Flow'!$A$6:$A$67,$A26,'Cash Flow'!H$6:H$67) -> 18813.53 | I26: =+SUMIF('Cash Flow'!$A$6:$A$67,$A26,'Cash Flow'!I$6:I$67) -> 18813.53 | J26: =+SUMIF('Cash Flow'!$A$6:$A$67,$A26,'Cash Flow'!J$6:J$67) -> 18813.53 | K26: =+SUMIF('Cash Flow'!$A$6:$A$67,$A26,'Cash Flow'!K$6:K$67) -> 18813.53 | ... P26: =+SUMIF('Cash Flow'!$A$6:$A$67,$A26,'Cash Flow'!P$6:P$67) -> 235454.17 | Q26: =SUM(E26:P26) -> 442403
A27: =+'Cash Flow'!A15 -> Interest From Bank Accounts | D27: =+SUMIF('Cash Flow'!$A$6:$A$67,$A27,'Cash Flow'!D$6:D$67) -> 388.31444 | E27: =+SUMIF('Cash Flow'!$A$6:$A$67,$A27,'Cash Flow'!E$6:E$67) -> 278.59048 | F27: =+SUMIF('Cash Flow'!$A$6:$A$67,$A27,'Cash Flow'!F$6:F$67) -> 253.9075 | G27: =+SUMIF('Cash Flow'!$A$6:$A$67,$A27,'Cash Flow'!G$6:G$67) -> 197.23535 | H27: =+SUMIF('Cash Flow'!$A$6:$A$67,$A27,'Cash Flow'!H$6:H$67) -> 135.68688 | I27: =+SUMIF('Cash Flow'!$A$6:$A$67,$A27,'Cash Flow'!I$6:I$67) -> 125.13627 | J27: =+SUMIF('Cash Flow'!$A$6:$A$67,$A27,'Cash Flow'!J$6:J$67) -> 96.6348 | K27: =+SUMIF('Cash Flow'!$A$6:$A$67,$A27,'Cash Flow'!K$6:K$67) -> 51.759487 | ... P27: =+SUMIF('Cash Flow'!$A$6:$A$67,$A27,'Cash Flow'!P$6:P$67) -> 5692.9393 | Q27: =SUM(E27:P27) -> 8661.3155
A28: =+'Cash Flow'!A16 -> Cash Income | D28: =+SUMIF('Cash Flow'!$A$6:$A$67,$A28,'Cash Flow'!D$6:D$67) -> 235842.49 | E28: =+SUMIF('Cash Flow'!$A$6:$A$67,$A28,'Cash Flow'!E$6:E$67) -> 19092.12 | F28: =+SUMIF('Cash Flow'!$A$6:$A$67,$A28,'Cash Flow'!F$6:F$67) -> 19067.437 | G28: =+SUMIF('Cash Flow'!$A$6:$A$67,$A28,'Cash Flow'!G$6:G$67) -> 19010.765 | H28: =+SUMIF('Cash Flow'!$A$6:$A$67,$A28,'Cash Flow'!H$6:H$67) -> 18949.217 | I28: =+SUMIF('Cash Flow'!$A$6:$A$67,$A28,'Cash Flow'!I$6:I$67) -> 18938.666 | J28: =+SUMIF('Cash Flow'!$A$6:$A$67,$A28,'Cash Flow'!J$6:J$67) -> 18910.164 | K28: =+SUMIF('Cash Flow'!$A$6:$A$67,$A28,'Cash Flow'!K$6:K$67) -> 18865.289 | ... P28: =+SUMIF('Cash Flow'!$A$6:$A$67,$A28,'Cash Flow'!P$6:P$67) -> 241147.11 | Q28: =SUM(E28:P28) -> 451064.32
A29: =+'Cash Flow'!A17 -> Rent on Primary Residence | D29: =+SUMIF('Cash Flow'!$A$6:$A$67,$A29,'Cash Flow'!D$6:D$67) -> 0 | E29: =+SUMIF('Cash Flow'!$A$6:$A$67,$A29,'Cash Flow'!E$6:E$67) -> 0 | F29: =+SUMIF('Cash Flow'!$A$6:$A$67,$A29,'Cash Flow'!F$6:F$67) -> 0 | G29: =+SUMIF('Cash Flow'!$A$6:$A$67,$A29,'Cash Flow'!G$6:G$67) -> 0 | H29: =+SUMIF('Cash Flow'!$A$6:$A$67,$A29,'Cash Flow'!H$6:H$67) -> 0 | I29: =+SUMIF('Cash Flow'!$A$6:$A$67,$A29,'Cash Flow'!I$6:I$67) -> 0 | J29: =+SUMIF('Cash Flow'!$A$6:$A$67,$A29,'Cash Flow'!J$6:J$67) -> 0 | K29: =+SUMIF('Cash Flow'!$A$6:$A$67,$A29,'Cash Flow'!K$6:K$67) -> 0 | ... P29: =+SUMIF('Cash Flow'!$A$6:$A$67,$A29,'Cash Flow'!P$6:P$67) -> 0 | Q29: =SUM(E29:P29) -> 0
A30: =+'Cash Flow'!A26 -> Manhattan Apartment | D30: =+SUMIF('Cash Flow'!$A$6:$A$67,$A30,'Cash Flow'!D$6:D$67) -> -4523.8817 | E30: =+SUMIF('Cash Flow'!$A$6:$A$67,$A30,'Cash Flow'!E$6:E$67) -> -22023.882 | F30: =+SUMIF('Cash Flow'!$A$6:$A$67,$A30,'Cash Flow'!F$6:F$67) -> -4523.8817 | G30: =+SUMIF('Cash Flow'!$A$6:$A$67,$A30,'Cash Flow'!G$6:G$67) -> -4523.8817 | H30: =+SUMIF('Cash Flow'!$A$6:$A$67,$A30,'Cash Flow'!H$6:H$67) -> -4523.8817 | I30: =+SUMIF('Cash Flow'!$A$6:$A$67,$A30,'Cash Flow'!I$6:I$67) -> -4523.8817 | J30: =+SUMIF('Cash Flow'!$A$6:$A$67,$A30,'Cash Flow'!J$6:J$67) -> -4523.8817 | K30: =+SUMIF('Cash Flow'!$A$6:$A$67,$A30,'Cash Flow'!K$6:K$67) -> -22023.882 | ... P30: =+SUMIF('Cash Flow'!$A$6:$A$67,$A30,'Cash Flow'!P$6:P$67) -> -4523.8817 | Q30: =SUM(E30:P30) -> -89286.58
A31: =+'Cash Flow'!A36 -> Florida Investment Property | D31: =+SUMIF('Cash Flow'!$A$6:$A$67,$A31,'Cash Flow'!D$6:D$67) -> -5075.73 | E31: =+SUMIF('Cash Flow'!$A$6:$A$67,$A31,'Cash Flow'!E$6:E$67) -> 1166.29 | F31: =+SUMIF('Cash Flow'!$A$6:$A$67,$A31,'Cash Flow'!F$6:F$67) -> 1166.29 | G31: =+SUMIF('Cash Flow'!$A$6:$A$67,$A31,'Cash Flow'!G$6:G$67) -> 1166.29 | H31: =+SUMIF('Cash Flow'!$A$6:$A$67,$A31,'Cash Flow'!H$6:H$67) -> 1166.29 | I31: =+SUMIF('Cash Flow'!$A$6:$A$67,$A31,'Cash Flow'!I$6:I$67) -> 1166.29 | J31: =+SUMIF('Cash Flow'!$A$6:$A$67,$A31,'Cash Flow'!J$6:J$67) -> 1166.29 | K31: =+SUMIF('Cash Flow'!$A$6:$A$67,$A31,'Cash Flow'!K$6:K$67) -> 1166.29 | ... P31: =+SUMIF('Cash Flow'!$A$6:$A$67,$A31,'Cash Flow'!P$6:P$67) -> -7632.61 | Q31: =SUM(E31:P31) -> 5196.58
A32: =+'Cash Flow'!A39 -> Alternative Investments | D32: =+SUMIF('Cash Flow'!$A$6:$A$67,$A32,'Cash Flow'!D$6:D$67) -> -677.08333 | E32: =+SUMIF('Cash Flow'!$A$6:$A$67,$A32,'Cash Flow'!E$6:E$67) -> -677.08333 | F32: =+SUMIF('Cash Flow'!$A$6:$A$67,$A32,'Cash Flow'!F$6:F$67) -> -677.08333 | G32: =+SUMIF('Cash Flow'!$A$6:$A$67,$A32,'Cash Flow'!G$6:G$67) -> -677.08333 | H32: =+SUMIF('Cash Flow'!$A$6:$A$67,$A32,'Cash Flow'!H$6:H$67) -> -677.08333 | I32: =+SUMIF('Cash Flow'!$A$6:$A$67,$A32,'Cash Flow'!I$6:I$67) -> -677.08333 | J32: =+SUMIF('Cash Flow'!$A$6:$A$67,$A32,'Cash Flow'!J$6:J$67) -> -677.08333 | K32: =+SUMIF('Cash Flow'!$A$6:$A$67,$A32,'Cash Flow'!K$6:K$67) -> -677.08333 | ... P32: =+SUMIF('Cash Flow'!$A$6:$A$67,$A32,'Cash Flow'!P$6:P$67) -> -677.08333 | Q32: =SUM(E32:P32) -> -8125
